Workbook

Sheet Inputs
A1: Post Holdings — Deleveraging Plan Model: Inputs
A2: Blue = input you can change; black = formula; yellow = key assumption. All $ in millions except per-share.
A3: Item | B3: Value | E3: Note | F3: Source
A4: Share price ($) | B4: 76.83 | E4: Latest Compustat daily price | F4: Compustat comp.secd via WRDS, 12-Oct-2026 (user's post_comps.py run)
A5: Shares outstanding (mm) | B5: 43.96 | E5: Market cap / price | F5: Compustat comp.secd: $3,377.2mm market cap / $76.83
A6: Net debt ($mm) | B6: 7360 | E6: Company-reported $7,410mm at 30-Jun-2026 | F6: Compustat comp.fundq (user's run); Post Q3 FY26 release
A7: Base Adj. EBITDA, FY27 starting point ($mm) | B7: 1480 | E7: Mgmt: FY26 guide less ~$60mm excess Foodservice and ~$20mm divested | F7: Post Q3 FY26 earnings release (6-Aug-2026), Outlook section
A9: EBITDA growth by year | B9: Base | C9: Downside
A10: FY2027 growth | B10: 0 | C10: -0.04 | E10: Mgmt: preliminary FY27 'generally flat' | F10: Q3 FY26 call commentary / user assumption
A11: FY2028 growth | B11: -0.01 | C11: -0.05 | E11: Assumption: cereal/pet volume declines (mgmt: long-term -1% to -2%) | F11: Q3 FY26 call commentary / user assumption
A12: FY2029 growth | B12: -0.01 | C12: -0.05 | E12: Assumption | F12: Q3 FY26 call commentary / user assumption
A14: Depreciation & amortization ($mm) | B14: 560 | E14: TTM D&A was $570mm | F14: Post Q3 FY26 release, net leverage reconciliation
A15: Capital expenditures ($mm) | B15: 350 | E15: FY26 guide $370–390mm incl. $80–90mm egg-facility projects | F15: Post Q3 FY26 release; FY27 lower = assumption
A16: Average interest rate on net debt | B16: 0.055 | E16: TTM interest $419mm / ~$7.6bn debt | F16: Post Q3 FY26 release
A17: Cash tax rate | B17: 0.245 | E17: Company's statutory blended rate | F17: Post Q3 FY26 release, footnotes
A18: Other cash items ($mm) | B18: -50 | E18: Restructuring, integration, working capital; calibrates model to TTM FCF of ~$553mm | F18: Assumption (see calibration on Model sheets)
A19: Status quo EV/EBITDA multiple | B19: =(B4*B5+B6)/B7 -> 7.2550316 | E19: Today's multiple on the FY27 base — held constant | F19: Formula
A20: Status quo leverage target (net debt / EBITDA) | B20: =B6/B7 -> 4.972973 | E20: Assumes mgmt keeps leverage flat and buys back stock with the rest | F20: Formula
A22: Activist plan levers
A23: Weetabix TTM Adj. EBITDA ($mm) | B23: 135.3 | E23: Q4 FY25 $32.6mm + 9M FY26 $102.7mm | F23: Post Q4 FY25 and Q3 FY26 earnings releases
A24: Weetabix sale multiple (EV/EBITDA) | B24: 10 | E24: UK #1 cereal brand; test 8x–12x | F24: Assumption
A25: Tax & fees leakage on sale | B25: 0.1 | E25: Placeholder — check tax basis in 10-K | F25: Assumption
A26: Weetabix capex ($mm) | B26: 25 | E26: Removed from Post's capex after sale | F26: Assumption
A27: Weetabix D&A ($mm) | B27: 46 | E27: FY25 segment D&A was $49mm | F27: Post Q4 FY25 release, segment reconciliation
A28: Stranded corporate costs ($mm / yr) | B28: 10 | E28: Overhead that doesn't leave with Weetabix | F28: Assumption
A29: Activist leverage target (net debt / EBITDA) | B29: 3.5 | E29: All FCF to debt until reached; buybacks resume after | F29: Assumption
A30: Upside case multiple: separation narrows the discount | B30: 8 | E30: Closes about two-thirds of the gap to the no-discount multiple in B32; requires separating Foodservice, not just deleveraging | F30: Assumption; see rows 31–32
A31: Post's historical multiple as % of peers | B31: 0.875 | E31: Average of 39 undistorted quarters, 2012–2026 (excludes 2014–15 and 2020–21); below peers in 37 of 39 | F31: post_history.py on Compustat quarterly data
A32: Multiple with no conglomerate discount | B32: =B19/B31 -> 8.2914647 | E32: Today's multiple grossed up to peer parity | F32: Formula

Sheet Model_Base
A1: Post Holdings — Base case projections ($mm)
C3: FY2027E | D3: FY2028E | E3: FY2029E
A5: STATUS QUO — keep leverage flat; free cash flow + new borrowing go to buybacks
A6: EBITDA growth | C6: =Inputs!$B$10 -> 0 | D6: =Inputs!$B$11 -> -0.01 | E6: =Inputs!$B$12 -> -0.01
A7: Adj. EBITDA | C7: =Inputs!$B$7*(1+C6) -> 1480 | D7: =C7*(1+D6) -> 1465.2 | E7: =D7*(1+E6) -> 1450.548
A8: Beginning net debt | C8: =Inputs!$B$6 -> 7360 | D8: =C17 -> 7360 | E8: =D17 -> 7286.4
A9: Beginning shares (mm) | C9: =Inputs!$B$5 -> 43.96 | D9: =C20 -> 36.814666 | E9: =D20 -> 31.754796
A10: Interest expense | C10: =C8*Inputs!$B$16 -> 404.8 | D10: =D8*Inputs!$B$16 -> 404.8 | E10: =E8*Inputs!$B$16 -> 400.752
A11: D&A (for taxes) | C11: =Inputs!$B$14 -> 560 | D11: =Inputs!$B$14 -> 560 | E11: =Inputs!$B$14 -> 560
A12: Capex | C12: =Inputs!$B$15 -> 350 | D12: =Inputs!$B$15 -> 350 | E12: =Inputs!$B$15 -> 350
A13: Cash taxes | C13: =MAX(0,C7-C11-C10)*Inputs!$B$17 -> 126.224 | D13: =MAX(0,D7-D11-D10)*Inputs!$B$17 -> 122.598 | E13: =MAX(0,E7-E11-E10)*Inputs!$B$17 -> 120.00002
A14: Other cash items | C14: =Inputs!$B$18 -> -50 | D14: =Inputs!$B$18 -> -50 | E14: =Inputs!$B$18 -> -50
A15: Free cash flow | C15: =C7-C12-C10-C13+C14 -> 548.976 | D15: =D7-D12-D10-D13+D14 -> 537.802 | E15: =E7-E12-E10-E13+E14 -> 529.79598
A16: Buybacks (FCF + borrowing to hold leverage) | C16: =MAX(0,C15+(Inputs!$B$20*C7-C8)) -> 548.976 | D16: =MAX(0,D15+(Inputs!$B$20*D7-D8)) -> 464.202 | E16: =MAX(0,E15+(Inputs!$B$20*E7-E8)) -> 456.93198
A17: Ending net debt | C17: =C8-C15+C16 -> 7360 | D17: =D8-D15+D16 -> 7286.4 | E17: =E8-E15+E16 -> 7213.536
A18: Buyback price ($/share, implied value at start of year) | C18: =Inputs!$B$4 -> 76.83 | D18: =MAX(1,(C7*Inputs!$B$19-D8)/D9) -> 91.741883 | E18: =MAX(1,(D7*Inputs!$B$19-E8)/E9) -> 105.29661
A19: Shares repurchased (mm) | C19: =C16/C18 -> 7.1453339 | D19: =D16/D18 -> 5.05987 | E19: =E16/E18 -> 4.3394748
A20: Ending shares (mm) | C20: =C9-C19 -> 36.814666 | D20: =D9-D19 -> 31.754796 | E20: =E9-E19 -> 27.415321
A21: Net debt / EBITDA | C21: =C17/C7 -> 4.972973 | D21: =D17/D7 -> 4.972973 | E21: =E17/E7 -> 4.972973
A23: ACTIVIST PLAN — sell Weetabix, pay down debt to target, then resume buybacks
A24: Weetabix EBITDA removed | C24: =Inputs!$B$23*(1+C6) -> 135.3 | D24: =C24*(1+D6) -> 133.947 | E24: =D24*(1+E6) -> 132.60753
A25: Adj. EBITDA (ex-Weetabix, less stranded costs) | C25: =C7-C24-Inputs!$B$28 -> 1334.7 | D25: =D7-D24-Inputs!$B$28 -> 1321.253 | E25: =E7-E24-Inputs!$B$28 -> 1307.9405
A26: Beginning net debt (FY27 after sale proceeds) | C26: =Inputs!$B$6-Inputs!$B$23*Inputs!$B$24*(1-Inputs!$B$25) -> 6142.3 | D26: =C36 -> 5638.7305 | E26: =D36 -> 5124.4028
A27: Beginning shares (mm) | C27: =Inputs!$B$5 -> 43.96 | D27: =C39 -> 43.96 | E27: =D39 -> 43.96
A28: Interest expense | C28: =C26*Inputs!$B$16 -> 337.8265 | D28: =D26*Inputs!$B$16 -> 310.13018 | E28: =E26*Inputs!$B$16 -> 281.84215
A29: D&A (for taxes) | C29: =Inputs!$B$14-Inputs!$B$27 -> 514 | D29: =Inputs!$B$14-Inputs!$B$27 -> 514 | E29: =Inputs!$B$14-Inputs!$B$27 -> 514
A30: Capex | C30: =Inputs!$B$15-Inputs!$B$26 -> 325 | D30: =Inputs!$B$15-Inputs!$B$26 -> 325 | E30: =Inputs!$B$15-Inputs!$B$26 -> 325
A31: Cash taxes | C31: =MAX(0,C25-C29-C28)*Inputs!$B$17 -> 118.30401 | D31: =MAX(0,D25-D29-D28)*Inputs!$B$17 -> 121.79509 | E31: =MAX(0,E25-E29-E28)*Inputs!$B$17 -> 125.46409
A32: Other cash items | C32: =Inputs!$B$18 -> -50 | D32: =Inputs!$B$18 -> -50 | E32: =Inputs!$B$18 -> -50
A33: Free cash flow | C33: =C25-C30-C28-C31+C32 -> 503.56949 | D33: =D25-D30-D28-D31+D32 -> 514.32773 | E33: =E25-E30-E28-E31+E32 -> 525.63423
A34: Debt paydown needed to reach target | C34: =MAX(0,C26-Inputs!$B$29*C25) -> 1470.85 | D34: =MAX(0,D26-Inputs!$B$29*D25) -> 1014.345 | E34: =MAX(0,E26-Inputs!$B$29*E25) -> 546.61113
A35: Buybacks (only FCF left after paydown) | C35: =MAX(0,C33-C34) -> 0 | D35: =MAX(0,D33-D34) -> 0 | E35: =MAX(0,E33-E34) -> 0
A36: Ending net debt | C36: =C26-C33+C35 -> 5638.7305 | D36: =D26-D33+D35 -> 5124.4028 | E36: =E26-E33+E35 -> 4598.7685
A37: Buyback price ($/share, implied value at activist multiple) | C37: =MAX(1,((Inputs!$B$7-Inputs!$B$23-Inputs!$B$28)*Inputs!$B$30-C26)/C27) -> 103.16879 | D37: =MAX(1,(C25*Inputs!$B$30-D26)/D27) -> 114.62396 | E37: =MAX(1,(D25*Inputs!$B$30-E26)/E27) -> 123.87673
A38: Shares repurchased (mm) | C38: =C35/C37 -> 0 | D38: =D35/D37 -> 0 | E38: =E35/E37 -> 0
A39: Ending shares (mm) | C39: =C27-C38 -> 43.96 | D39: =D27-D38 -> 43.96 | E39: =E27-E38 -> 43.96
A40: Net debt / EBITDA | C40: =C36/C25 -> 4.2247175 | D40: =D36/D25 -> 3.8784417 | E40: =E36/E25 -> 3.5160381
A42: CALIBRATION CHECK — model FCF on TTM inputs vs. actual TTM free cash flow
A43: Modeled FCF at TTM levels (TTM EBITDA $1,616mm, capex $440mm, interest $419mm) | C43: =1615.9-439.5-419.1-MAX(0,1615.9-570.4-419.1)*Inputs!$B$17+Inputs!$B$18 -> 553.832
A44: Actual TTM free cash flow (FY25 FCF $488.1mm − 9M FY25 $336.5mm + 9M FY26 $401.5mm) | C44: 553.1
...

Sheet Model_Downside
A1: Post Holdings — Downside case projections ($mm)
C3: FY2027E | D3: FY2028E | E3: FY2029E
A5: STATUS QUO — keep leverage flat; free cash flow + new borrowing go to buybacks
A6: EBITDA growth | C6: =Inputs!$C$10 -> -0.04 | D6: =Inputs!$C$11 -> -0.05 | E6: =Inputs!$C$12 -> -0.05
A7: Adj. EBITDA | C7: =Inputs!$B$7*(1+C6) -> 1420.8 | D7: =C7*(1+D6) -> 1349.76 | E7: =D7*(1+E6) -> 1282.272
A8: Beginning net debt | C8: =Inputs!$B$6 -> 7360 | D8: =C17 -> 7065.6 | E8: =D17 -> 6712.32
A9: Beginning shares (mm) | C9: =Inputs!$B$5 -> 43.96 | D9: =C20 -> 41.228255 | E9: =D20 -> 39.83476
A10: Interest expense | C10: =C8*Inputs!$B$16 -> 404.8 | D10: =D8*Inputs!$B$16 -> 388.608 | E10: =E8*Inputs!$B$16 -> 369.1776
A11: D&A (for taxes) | C11: =Inputs!$B$14 -> 560 | D11: =Inputs!$B$14 -> 560 | E11: =Inputs!$B$14 -> 560
A12: Capex | C12: =Inputs!$B$15 -> 350 | D12: =Inputs!$B$15 -> 350 | E12: =Inputs!$B$15 -> 350
A13: Cash taxes | C13: =MAX(0,C7-C11-C10)*Inputs!$B$17 -> 111.72 | D13: =MAX(0,D7-D11-D10)*Inputs!$B$17 -> 98.28224 | E13: =MAX(0,E7-E11-E10)*Inputs!$B$17 -> 86.508128
A14: Other cash items | C14: =Inputs!$B$18 -> -50 | D14: =Inputs!$B$18 -> -50 | E14: =Inputs!$B$18 -> -50
A15: Free cash flow | C15: =C7-C12-C10-C13+C14 -> 504.28 | D15: =D7-D12-D10-D13+D14 -> 462.86976 | E15: =E7-E12-E10-E13+E14 -> 426.58627
A16: Buybacks (FCF + borrowing to hold leverage) | C16: =MAX(0,C15+(Inputs!$B$20*C7-C8)) -> 209.88 | D16: =MAX(0,D15+(Inputs!$B$20*D7-D8)) -> 109.58976 | E16: =MAX(0,E15+(Inputs!$B$20*E7-E8)) -> 90.970272
A17: Ending net debt | C17: =C8-C15+C16 -> 7065.6 | D17: =D8-D15+D16 -> 6712.32 | E17: =E8-E15+E16 -> 6376.704
A18: Buyback price ($/share, implied value at start of year) | C18: =Inputs!$B$4 -> 76.83 | D18: =MAX(1,(C7*Inputs!$B$19-D8)/D9) -> 78.643856 | E18: =MAX(1,(D7*Inputs!$B$19-E8)/E9) -> 77.325217
A19: Shares repurchased (mm) | C19: =C16/C18 -> 2.7317454 | D19: =D16/D18 -> 1.3934942 | E19: =E16/E18 -> 1.1764632
A20: Ending shares (mm) | C20: =C9-C19 -> 41.228255 | D20: =D9-D19 -> 39.83476 | E20: =E9-E19 -> 38.658297
A21: Net debt / EBITDA | C21: =C17/C7 -> 4.972973 | D21: =D17/D7 -> 4.972973 | E21: =E17/E7 -> 4.972973
A23: ACTIVIST PLAN — sell Weetabix, pay down debt to target, then resume buybacks
A24: Weetabix EBITDA removed | C24: =Inputs!$B$23*(1+C6) -> 129.888 | D24: =C24*(1+D6) -> 123.3936 | E24: =D24*(1+E6) -> 117.22392
A25: Adj. EBITDA (ex-Weetabix, less stranded costs) | C25: =C7-C24-Inputs!$B$28 -> 1280.912 | D25: =D7-D24-Inputs!$B$28 -> 1216.3664 | E25: =E7-E24-Inputs!$B$28 -> 1155.0481
A26: Beginning net debt (FY27 after sale proceeds) | C26: =Inputs!$B$6-Inputs!$B$23*Inputs!$B$24*(1-Inputs!$B$25) -> 6142.3 | D26: =C36 -> 5679.3404 | E26: =D36 -> 5245.8884
A27: Beginning shares (mm) | C27: =Inputs!$B$5 -> 43.96 | D27: =C39 -> 43.96 | E27: =D39 -> 43.96
A28: Interest expense | C28: =C26*Inputs!$B$16 -> 337.8265 | D28: =D26*Inputs!$B$16 -> 312.36372 | E28: =E26*Inputs!$B$16 -> 288.52386
A29: D&A (for taxes) | C29: =Inputs!$B$14-Inputs!$B$27 -> 514 | D29: =Inputs!$B$14-Inputs!$B$27 -> 514 | E29: =Inputs!$B$14-Inputs!$B$27 -> 514
A30: Capex | C30: =Inputs!$B$15-Inputs!$B$26 -> 325 | D30: =Inputs!$B$15-Inputs!$B$26 -> 325 | E30: =Inputs!$B$15-Inputs!$B$26 -> 325
A31: Cash taxes | C31: =MAX(0,C25-C29-C28)*Inputs!$B$17 -> 105.12595 | D31: =MAX(0,D25-D29-D28)*Inputs!$B$17 -> 95.550655 | E31: =MAX(0,E25-E29-E28)*Inputs!$B$17 -> 86.368433
A32: Other cash items | C32: =Inputs!$B$18 -> -50 | D32: =Inputs!$B$18 -> -50 | E32: =Inputs!$B$18 -> -50
A33: Free cash flow | C33: =C25-C30-C28-C31+C32 -> 462.95955 | D33: =D25-D30-D28-D31+D32 -> 433.45202 | E33: =E25-E30-E28-E31+E32 -> 405.15578
A34: Debt paydown needed to reach target | C34: =MAX(0,C26-Inputs!$B$29*C25) -> 1659.108 | D34: =MAX(0,D26-Inputs!$B$29*D25) -> 1422.058 | E34: =MAX(0,E26-Inputs!$B$29*E25) -> 1203.2201
A35: Buybacks (only FCF left after paydown) | C35: =MAX(0,C33-C34) -> 0 | D35: =MAX(0,D33-D34) -> 0 | E35: =MAX(0,E33-E34) -> 0
A36: Ending net debt | C36: =C26-C33+C35 -> 5679.3404 | D36: =D26-D33+D35 -> 5245.8884 | E36: =E26-E33+E35 -> 4840.7326
A37: Buyback price ($/share, implied value at activist multiple) | C37: =MAX(1,((Inputs!$B$7-Inputs!$B$23-Inputs!$B$28)*Inputs!$B$30-C26)/C27) -> 103.16879 | D37: =MAX(1,(C25*Inputs!$B$30-D26)/D27) -> 103.91164 | E37: =MAX(1,(D25*Inputs!$B$30-E26)/E27) -> 102.02554
A38: Shares repurchased (mm) | C38: =C35/C37 -> 0 | D38: =D35/D37 -> 0 | E38: =E35/E37 -> 0
A39: Ending shares (mm) | C39: =C27-C38 -> 43.96 | D39: =D27-D38 -> 43.96 | E39: =E27-E38 -> 43.96
A40: Net debt / EBITDA | C40: =C36/C25 -> 4.4338256 | D40: =D36/D25 -> 4.3127535 | E40: =E36/E25 -> 4.1909361
A42: CALIBRATION CHECK — model FCF on TTM inputs vs. actual TTM free cash flow
A43: Modeled FCF at TTM levels (TTM EBITDA $1,616mm, capex $440mm, interest $419mm) | C43: =1615.9-439.5-419.1-MAX(0,1615.9-570.4-419.1)*Inputs!$B$17+Inputs!$B$18 -> 553.832
A44: Actual TTM free cash flow (FY25 FCF $488.1mm − 9M FY25 $336.5mm + 9M FY26 $401.5mm) | C44: 553.1
...

Sheet Valuation
A1: Value per share at end of FY2029 — status quo vs. activist plan
A3: Base case
A4: Plan | B4: Multiple | C4: FY29 EBITDA | D4: Enterprise value | E4: Net debt | F4: Equity value | G4: Shares (mm) | H4: Value / share | I4: vs. today | J4: Annual return
A5: Status quo (today's multiple) | B5: =Inputs!$B$19 -> 7.2550316 | C5: =Model_Base!$E$7 -> 1450.548 | D5: =B5*C5 -> 10523.772 | E5: =Model_Base!$E$17 -> 7213.536 | F5: =D5-E5 -> 3310.2356 | G5: =Model_Base!$E$20 -> 27.415321 | H5: =IF(G5>0,F5/G5,0) -> 120.744 | I5: =H5/Inputs!$B$4-1 -> 0.57157363 | J5: =IF(H5>0,(H5/Inputs!$B$4)^(1/3)-1,-1) -> 0.16263906
A6: Activist plan — today's multiple (core case) | B6: =Inputs!$B$19 -> 7.2550316 | C6: =Model_Base!$E$25 -> 1307.9405 | D6: =B6*C6 -> 9489.1495 | E6: =Model_Base!$E$36 -> 4598.7685 | F6: =D6-E6 -> 4890.3809 | G6: =Model_Base!$E$39 -> 43.96 | H6: =IF(G6>0,F6/G6,0) -> 111.24615 | I6: =H6/Inputs!$B$4-1 -> 0.44795202 | J6: =IF(H6>0,(H6/Inputs!$B$4)^(1/3)-1,-1) -> 0.13131807
A7: Activist plan + separation upside | B7: =Inputs!$B$30 -> 8 | C7: =Model_Base!$E$25 -> 1307.9405 | D7: =B7*C7 -> 10463.524 | E7: =Model_Base!$E$36 -> 4598.7685 | F7: =D7-E7 -> 5864.7552 | G7: =Model_Base!$E$39 -> 43.96 | H7: =IF(G7>0,F7/G7,0) -> 133.41117 | I7: =H7/Inputs!$B$4-1 -> 0.73644636 | J7: =IF(H7>0,(H7/Inputs!$B$4)^(1/3)-1,-1) -> 0.201952
A9: Downside case
A10: Plan | B10: Multiple | C10: FY29 EBITDA | D10: Enterprise value | E10: Net debt | F10: Equity value | G10: Shares (mm) | H10: Value / share | I10: vs. today | J10: Annual return
A11: Status quo (today's multiple) | B11: =Inputs!$B$19 -> 7.2550316 | C11: =Model_Downside!$E$7 -> 1282.272 | D11: =B11*C11 -> 9302.9239 | E11: =Model_Downside!$E$17 -> 6376.704 | F11: =D11-E11 -> 2926.2199 | G11: =Model_Downside!$E$20 -> 38.658297 | H11: =IF(G11>0,F11/G11,0) -> 75.694485 | I11: =H11/Inputs!$B$4-1 -> -0.014779574 | J11: =IF(H11>0,(H11/Inputs!$B$4)^(1/3)-1,-1) -> -0.0049509965
A12: Activist plan — today's multiple (core case) | B12: =Inputs!$B$19 -> 7.2550316 | C12: =Model_Downside!$E$25 -> 1155.0481 | D12: =B12*C12 -> 8379.9103 | E12: =Model_Downside!$E$36 -> 4840.7326 | F12: =D12-E12 -> 3539.1777 | G12: =Model_Downside!$E$39 -> 43.96 | H12: =IF(G12>0,F12/G12,0) -> 80.509047 | I12: =H12/Inputs!$B$4-1 -> 0.047885551 | J12: =IF(H12>0,(H12/Inputs!$B$4)^(1/3)-1,-1) -> 0.015713639
A13: Activist plan + separation upside | B13: =Inputs!$B$30 -> 8 | C13: =Model_Downside!$E$25 -> 1155.0481 | D13: =B13*C13 -> 9240.3846 | E13: =Model_Downside!$E$36 -> 4840.7326 | F13: =D13-E13 -> 4399.652 | G13: =Model_Downside!$E$39 -> 43.96 | H13: =IF(G13>0,F13/G13,0) -> 100.08308 | I13: =H13/Inputs!$B$4-1 -> 0.30265619 | J13: =IF(H13>0,(H13/Inputs!$B$4)^(1/3)-1,-1) -> 0.092135698
A15: Value bridge — base case ($ per share)
A16: Share price today | B16: =Inputs!$B$4 -> 76.83
A17: Plus: status quo value creation (buybacks at constant multiple) | B17: =H5-Inputs!$B$4 -> 43.914002
A18: Plus: plan vs. status quo at same multiple (sale + deleveraging) | B18: =H6-H5 -> -9.4978479
A19: Plus: separation narrows the conglomerate discount (upside) | B19: =H7-H6 -> 22.16502
A20: Activist plan with separation upside (end FY29) | B20: =SUM(B16:B19) -> 133.41117
A22: Downside case: how much each plan loses vs. base
A23: Status quo value/share, downside vs. base | B23: =H11/H5-1 -> -0.37309941
A24: Activist plan (today's multiple), downside vs. base | B24: =H12/H6-1 -> -0.27629815
A25: Status quo net debt / EBITDA at end FY29, downside | B25: =Model_Downside!$E$21 -> 4.972973
A26: Activist plan net debt / EBITDA at end FY29, downside | B26: =Model_Downside!$E$40 -> 4.1909361
A28: Sensitivity (base case): value per share at end FY29 by exit multiple
A29: Exit multiple | B29: Status quo | C29: Activist plan
A30: 6 | B30: =(A30*Model_Base!$E$7-Model_Base!$E$17)/Model_Base!$E$20 -> 54.340125 | C30: =(A30*Model_Base!$E$25-Model_Base!$E$36)/Model_Base!$E$39 -> 73.905238
A31: 6.5 | B31: =(A31*Model_Base!$E$7-Model_Base!$E$17)/Model_Base!$E$20 -> 80.795186 | C31: =(A31*Model_Base!$E$25-Model_Base!$E$36)/Model_Base!$E$39 -> 88.781722
A32: 7 | B32: =(A32*Model_Base!$E$7-Model_Base!$E$17)/Model_Base!$E$20 -> 107.25025 | C32: =(A32*Model_Base!$E$25-Model_Base!$E$36)/Model_Base!$E$39 -> 103.65821
A33: 7.5 | B33: =(A33*Model_Base!$E$7-Model_Base!$E$17)/Model_Base!$E$20 -> 133.70531 | C33: =(A33*Model_Base!$E$25-Model_Base!$E$36)/Model_Base!$E$39 -> 118.53469
A34: 8 | B34: =(A34*Model_Base!$E$7-Model_Base!$E$17)/Model_Base!$E$20 -> 160.16037 | C34: =(A34*Model_Base!$E$25-Model_Base!$E$36)/Model_Base!$E$39 -> 133.41117
A35: 8.5 | B35: =(A35*Model_Base!$E$7-Model_Base!$E$17)/Model_Base!$E$20 -> 186.61543 | C35: =(A35*Model_Base!$E$25-Model_Base!$E$36)/Model_Base!$E$39 -> 148.28766
A36: 9 | B36: =(A36*Model_Base!$E$7-Model_Base!$E$17)/Model_Base!$E$20 -> 213.07049 | C36: =(A36*Model_Base!$E$25-Model_Base!$E$36)/Model_Base!$E$39 -> 163.16414
A38: Note: the sensitivity changes only the exit multiple; buyback prices inside the model keep the multiples on the Inputs sheet.

Sheet Spin_Off
A1: Foodservice spin-off: what would the two companies be worth?
A2: Each Post share receives one share of the spun-off Foodservice company ('SpinCo'). SpinCo takes on debt at its own target leverage; the rest stays with Post ('RemainCo').
A4: Spin-off inputs
A5: Foodservice normalized EBITDA, FY27 ($mm) | B5: 500 | E5: Management: ~$500mm normalized annual run rate | F5: Post Q3 FY26 earnings release
A6: SpinCo standalone public-company costs ($mm / yr) | B6: 30 | E6: New board, CFO, listing, audit, IT | F6: Assumption
A7: One-time separation costs ($mm) | B7: 75 | E7: Advisers, systems, refinancing; added to debt | F7: Assumption
A8: SpinCo net debt / EBITDA at spin | B8: 3 | E8: Typical for a newly spun food company | F8: Assumption
A9: SpinCo EV/EBITDA multiple | B9: 9.5 | E9: Lamb Weston ~10x; discounted for egg-price cyclicality | F9: post_comps.py; assumption
A10: RemainCo EV/EBITDA multiple | B10: =Inputs!B19 -> 7.2550316 | E10: Today's Post multiple (no re-rating) — try 8.0x for peer-like | F10: Link to Inputs
A12: Pro forma values | B12: Spin today (after Weetabix sale) | C12: Spin at end of FY2029 (after paydown) | D12: Spin at end of FY2029, downside case
A13: Post EBITDA ex-Weetabix | B13: =Inputs!$B$7-Inputs!$B$23-Inputs!$B$28 -> 1334.7 | C13: =Model_Base!$E$25 -> 1307.9405 | D13: =Model_Downside!$E$25 -> 1155.0481
A14: Foodservice EBITDA | B14: =$B$5 -> 500 | C14: =$B$5*(1+Model_Base!$C$6)*(1+Model_Base!$D$6)*(1+Model_Base!$E$6) -> 490.05 | D14: =$B$5*(1+Model_Downside!$C$6)*(1+Model_Downside!$D$6)*(1+Model_Downside!$E$6) -> 433.2
A15: Less: SpinCo standalone costs | B15: =-$B$6 -> -30 | C15: =-$B$6 -> -30 | D15: =-$B$6 -> -30
A16: SpinCo EBITDA | B16: =B14+B15 -> 470 | C16: =C14+C15 -> 460.05 | D16: =D14+D15 -> 403.2
A17: RemainCo EBITDA | B17: =B13-B14 -> 834.7 | C17: =C13-C14 -> 817.89047 | D17: =D13-D14 -> 721.84808
A18: Net debt before spin | B18: =Inputs!$B$6-Inputs!$B$23*Inputs!$B$24*(1-Inputs!$B$25) -> 6142.3 | C18: =Model_Base!$E$36 -> 4598.7685 | D18: =Model_Downside!$E$36 -> 4840.7326
A19: Plus: one-time separation costs | B19: =$B$7 -> 75 | C19: =$B$7 -> 75 | D19: =$B$7 -> 75
A20: SpinCo net debt | B20: =$B$8*B16 -> 1410 | C20: =$B$8*C16 -> 1380.15 | D20: =$B$8*D16 -> 1209.6
A21: RemainCo net debt | B21: =B18+B19-B20 -> 4807.3 | C21: =C18+C19-C20 -> 3293.6185 | D21: =D18+D19-D20 -> 3706.1326
A22: RemainCo net debt / EBITDA | B22: =B21/B17 -> 5.7593147 | C22: =C21/C17 -> 4.0269678 | D22: =D21/D17 -> 5.134228
A23: SpinCo enterprise value | B23: =$B$9*B16 -> 4465 | C23: =$B$9*C16 -> 4370.475 | D23: =$B$9*D16 -> 3830.4
A24: SpinCo equity value | B24: =B23-B20 -> 3055 | C24: =C23-C20 -> 2990.325 | D24: =D23-D20 -> 2620.8
A25: RemainCo enterprise value | B25: =$B$10*B17 -> 6055.7749 | C25: =$B$10*C17 -> 5933.8212 | D25: =$B$10*D17 -> 5237.0306
A26: RemainCo equity value | B26: =B25-B21 -> 1248.4749 | C26: =C25-C21 -> 2640.2027 | D26: =D25-D21 -> 1530.898
A27: Combined equity value | B27: =B24+B26 -> 4303.4749 | C27: =C24+C26 -> 5630.5277 | D27: =D24+D26 -> 4151.698
A28: Post shares (mm) | B28: =Inputs!$B$5 -> 43.96 | C28: =Model_Base!$E$39 -> 43.96 | D28: =Model_Downside!$E$39 -> 43.96
A29: Value per Post share (SpinCo + RemainCo) | B29: =B27/B28 -> 97.895243 | C29: =C27/C28 -> 128.08298 | D29: =D27/D28 -> 94.44263
A30: Compare: no spin, same date, today's multiple | B30: =Inputs!$B$4 -> 76.83 | C30: =Valuation!$H$6 -> 111.24615 | D30: =Valuation!$H$12 -> 80.509047
A31: Value added by the spin-off, per share | B31: =B29-B30 -> 21.065243 | C31: =C29-C30 -> 16.836823 | D31: =D29-D30 -> 13.933583
A32: Implied multiple for Post as a whole | B32: =(B23+B25)/B13 -> 7.8825016 | C32: =(C23+C25)/C13 -> 7.8782609 | D32: =(D23+D25)/D13 -> 7.8502625
A33: Row 30, today column: today's share price. FY2029 column: the activist plan's core-case value (Valuation sheet), so row 31 isolates what the separation itself adds.
A35: Sensitivity: value per Post share, spin at end of FY2029
A36: RemainCo multiple ↓ / SpinCo multiple → | B36: 8.5 | C36: 9 | D36: 9.5 | E36: 10 | F36: 10.5
A37: 6.5 | B37: =(B$36*$C$16-$C$20+$A37*$C$17-$C$21)/$C$28 -> 103.57017 | C37: =(C$36*$C$16-$C$20+$A37*$C$17-$C$21)/$C$28 -> 108.80276 | D37: =(D$36*$C$16-$C$20+$A37*$C$17-$C$21)/$C$28 -> 114.03536 | E37: =(E$36*$C$16-$C$20+$A37*$C$17-$C$21)/$C$28 -> 119.26796 | F37: =(F$36*$C$16-$C$20+$A37*$C$17-$C$21)/$C$28 -> 124.50056
A38: 7 | B38: =(B$36*$C$16-$C$20+$A38*$C$17-$C$21)/$C$28 -> 112.87283 | C38: =(C$36*$C$16-$C$20+$A38*$C$17-$C$21)/$C$28 -> 118.10543 | D38: =(D$36*$C$16-$C$20+$A38*$C$17-$C$21)/$C$28 -> 123.33803 | E38: =(E$36*$C$16-$C$20+$A38*$C$17-$C$21)/$C$28 -> 128.57063 | F38: =(F$36*$C$16-$C$20+$A38*$C$17-$C$21)/$C$28 -> 133.80322
A39: 7.5 | B39: =(B$36*$C$16-$C$20+$A39*$C$17-$C$21)/$C$28 -> 122.1755 | C39: =(C$36*$C$16-$C$20+$A39*$C$17-$C$21)/$C$28 -> 127.4081 | D39: =(D$36*$C$16-$C$20+$A39*$C$17-$C$21)/$C$28 -> 132.6407 | E39: =(E$36*$C$16-$C$20+$A39*$C$17-$C$21)/$C$28 -> 137.87329 | F39: =(F$36*$C$16-$C$20+$A39*$C$17-$C$21)/$C$28 -> 143.10589
A40: 8 | B40: =(B$36*$C$16-$C$20+$A40*$C$17-$C$21)/$C$28 -> 131.47817 | C40: =(C$36*$C$16-$C$20+$A40*$C$17-$C$21)/$C$28 -> 136.71076 | D40: =(D$36*$C$16-$C$20+$A40*$C$17-$C$21)/$C$28 -> 141.94336 | E40: =(E$36*$C$16-$C$20+$A40*$C$17-$C$21)/$C$28 -> 147.17596 | F40: =(F$36*$C$16-$C$20+$A40*$C$17-$C$21)/$C$28 -> 152.40856
A41: 8.5 | B41: =(B$36*$C$16-$C$20+$A41*$C$17-$C$21)/$C$28 -> 140.78083 | C41: =(C$36*$C$16-$C$20+$A41*$C$17-$C$21)/$C$28 -> 146.01343 | D41: =(D$36*$C$16-$C$20+$A41*$C$17-$C$21)/$C$28 -> 151.24603 | E41: =(E$36*$C$16-$C$20+$A41*$C$17-$C$21)/$C$28 -> 156.47863 | F41: =(F$36*$C$16-$C$20+$A41*$C$17-$C$21)/$C$28 -> 161.71122

Sheet Buyback_Check
A1: What Post's recent buybacks are worth today
A3: Period | B3: Shares bought (mm) | C3: Amount spent ($mm) | D3: Avg. price ($) | E3: Value today ($mm) | F3: Gain / (loss) ($mm) | G3: Source
A4: FY2025 (Oct-2024 – Sep-2025) | B4: 6.45 | C4: 708.5 | D4: =C4/B4 -> 109.84496 | E4: =B4*Inputs!$B$4 -> 495.5535 | F4: =E4-C4 -> -212.9465 | G4: Post Q4 FY25 earnings release, Share Repurchases
A5: FY2026 through 5-Aug-2026 | B5: 9.5 | C5: 948.1 | D5: =C5/B5 -> 99.8 | E5: =B5*Inputs!$B$4 -> 729.885 | F5: =E5-C5 -> -218.215 | G5: Post Q3 FY26 release: 9.1mm / $908.8mm in 9M FY26 + 0.4mm / $39.3mm to 5-Aug
A6: Total | B6: =SUM(B4:B5) -> 15.95 | C6: =SUM(C4:C5) -> 1656.6 | D6: =C6/B6 -> 103.86207 | E6: =SUM(E4:E5) -> 1225.4385 | F6: =SUM(F4:F5) -> -431.1615
A8: Alternative: if the same cash had repaid debt
A9: Marginal borrowing rate (recent 6.25% senior notes) | B9: 0.0625
A10: Annual interest saved ($mm) | B10: =C6*B9 -> 103.5375
A11: Net leverage if repaid instead (on TTM Adj. EBITDA $1,616mm) | B11: =(Inputs!$B$6-C6)/1615.9 -> 3.5295501

Sheet Notes
A1: How to use this model
A2: 1. Change blue cells on the Inputs sheet; everything else recalculates.
A3: 2. Model_Base and Model_Downside run the same plan under the two EBITDA growth paths on Inputs.
A4: 3. Valuation compares end-FY2029 value per share for the status quo and the activist plan, with a bridge and an exit-multiple sensitivity.
A5: 4. Spin_Off values Foodservice and the rest of Post separately, either today (after the Weetabix sale) or at the end of FY2029 (after debt paydown), with a multiple sensitivity grid.
A6: 5. Buyback_Check shows the market value today of shares Post repurchased in FY2025–FY2026.
A8: Key simplifications
A9: - Interest is charged on beginning-of-year net debt (avoids circular references).
A10: - Buyback prices equal the implied value per share at the start of each year at the plan's multiple, so buybacks get more expensive as value rises.
A11: - Weetabix is assumed sold on 1-Oct-2026 with proceeds used to repay debt; its EBITDA follows the same growth path as the rest of Post.
A12: - EBITDA is Post's Adjusted EBITDA; peer multiples from Compustat use as-reported EBITDA, so compare re-rating assumptions with care.
A13: - Post's own history (post_history.py) shows no re-rating when leverage was lower: its discount to peers has persisted at all leverage levels. The core case therefore holds today's multiple; the upside case assumes separation, not deleveraging, narrows the discount.
... A19: - Compustat (comp.secd, comp.fundq) via WRDS, pulled by post_comps.py on 12-Oct-2026.
